{"tag": "function", "depth": 1, "time": 1718764856.48998, "data": {"name": "connect_device", "call_args": {"uri": "android://127.0.0.1:5037/PFT4PBLF75GQHYBM?cap_method=JAVACAP&&ori_method=JAVACAPORI&&touch_method=JAVATOUCH"}, "start_time": 1718764851.445032, "traceback": "Traceback (most recent call last):\n  File \"airtest/core/android/adb.py\", line 340, in wait_for_device\n  File \"airtest/core/android/adb.py\", line 220, in cmd\n  File \"airtest/utils/compat.py\", line 79, in proc_communicate_timeout\n  File \"<string>\", line 3, in raise_from\nRuntimeError: Command ['/Applications/AirtestIDE.app/Contents/MacOS/airtest/core/android/static/adb/mac/adb', '-P', '5037', '-s', 'PFT4PBLF75GQHYBM', 'wait-for-device'] timed out after 5 seconds: stdout['b'''], stderr['b''']\n\nThe above exception was the direct cause of the following exception:\n\nTraceback (most recent call last):\n  File \"airtest/utils/logwraper.py\", line 131, in wrapper\n  File \"airtest/core/api.py\", line 74, in connect_device\n  File \"airtest/core/api.py\", line 42, in init_device\n  File \"airtest/core/android/android.py\", line 59, in __init__\n  File \"airtest/core/android/adb.py\", line 342, in wait_for_device\n  File \"airtest/utils/compat.py\", line 55, in raisefrom\n  File \"<string>\", line 3, in raise_from\nairtest.core.error.DeviceConnectionError: 'device not ready'\n", "end_time": 1718764856.489915}}
{"tag": "info", "depth": 0, "time": 1718764856.49369, "data": {"name": "Final Error", "traceback": "Traceback (most recent call last):\n  File \"airtest/core/android/adb.py\", line 340, in wait_for_device\n  File \"airtest/core/android/adb.py\", line 220, in cmd\n  File \"airtest/utils/compat.py\", line 79, in proc_communicate_timeout\n  File \"<string>\", line 3, in raise_from\nRuntimeError: Command ['/Applications/AirtestIDE.app/Contents/MacOS/airtest/core/android/static/adb/mac/adb', '-P', '5037', '-s', 'PFT4PBLF75GQHYBM', 'wait-for-device'] timed out after 5 seconds: stdout['b'''], stderr['b''']\n\nThe above exception was the direct cause of the following exception:\n\nTraceback (most recent call last):\n  File \"airtest/cli/runner.py\", line 72, in runTest\n  File \"/Users/carlos/PycharmProjects/Airtest_demo/\u5b98\u65b9\u6d4b\u8bd5\u6587\u6863/pro02.air/pro02.py\", line 18, in <module>\n    auto_setup(__file__,devices=[\"android://127.0.0.1:5037/PFT4PBLF75GQHYBM?cap_method=JAVACAP&&ori_method=JAVACAPORI&&touch_method=JAVATOUCH\"],logdir=r\"D:\\test\\pro01_log\")\n  File \"airtest/core/api.py\", line 141, in auto_setup\n  File \"airtest/utils/logwraper.py\", line 131, in wrapper\n  File \"airtest/core/api.py\", line 74, in connect_device\n  File \"airtest/core/api.py\", line 42, in init_device\n  File \"airtest/core/android/android.py\", line 59, in __init__\n  File \"airtest/core/android/adb.py\", line 342, in wait_for_device\n  File \"airtest/utils/compat.py\", line 55, in raisefrom\n  File \"<string>\", line 3, in raise_from\nairtest.core.error.DeviceConnectionError: 'device not ready'\n"}}
